Workbook

Sheet Calc
A1: Job | B1: The Ballroom | D1: Status | E1: Draft
A2: Job Date | D2: Revision
A3: Designer | B3: Mark Hughes | D3: Load over people?
A4: Venue | D4: Top rigging included? | E4: Yes
A5: Sub System | B5: Main Hang Left | D5: Hoist orientation | E5: Body down
A6: Point ID / Location
A8: NOTES | B8: ITEM | C8: Item Kg or Kg/m | D8: Length (m) | E8: Line Weight | F8: Qty | G8: Total Weight | H8: SWL / WLL (kg) | I8: Carried load (static) | J8: Carried load (+ contingency) | K8: Used
A9: TOP RIGGING – above the hoist (list top-down) | F9: Subtotal | G9: =SUM(G10:G12) -> 0
A10: Steel | B10: Wire rope sling 10mm 1,280 Kg SWL EN13414-1:2003 | C10: =IF($B10="","",IFERROR(VLOOKUP($B10,SPEC,2,0),"NOT FOUND")) -> TBC | D10: 1 | E10: =IF($B10="","",IF(NOT(ISNUMBER($C10)),"CHECK",IF(VLOOKUP($B10,SPEC,3,0)="per m",IF(N($D10)=0,"LEN?",$C10*$D10),$C10))) -> CHECK | F10: 1 | G10: =IF($B10="","",IF(ISNUMBER($E10),$E10*N($F10),"CHECK")) -> CHECK | H10: =IF($B10="","",IF(N(IFERROR(VLOOKUP($B10,SPEC,4,0),0))>0,VLOOKUP($B10,SPEC,4,0),"–")) -> 1280 | I10: =IF(ISNUMBER($H10),SUM($G$11:$G$12)+$G$13+$G$22+$G$27+$G$34,"") -> 444.662 | J10: =IF(ISNUMBER($I10),$I10*(1+N($F$46)),"") -> 466.8951 | K10: =IF(ISNUMBER($J10),$J10/$H10,"") -> 0.3647618
C11: =IF($B11="","",IFERROR(VLOOKUP($B11,SPEC,2,0),"NOT FOUND")) | E11: =IF($B11="","",IF(NOT(ISNUMBER($C11)),"CHECK",IF(VLOOKUP($B11,SPEC,3,0)="per m",IF(N($D11)=0,"LEN?",$C11*$D11),$C11))) | G11: =IF($B11="","",IF(ISNUMBER($E11),$E11*N($F11),"CHECK")) | H11: =IF($B11="","",IF(N(IFERROR(VLOOKUP($B11,SPEC,4,0),0))>0,VLOOKUP($B11,SPEC,4,0),"–")) | I11: =IF(ISNUMBER($H11),SUM($G$12:$G$12)+$G$13+$G$22+$G$27+$G$34,"") | J11: =IF(ISNUMBER($I11),$I11*(1+N($F$46)),"") | K11: =IF(ISNUMBER($J11),$J11/$H11,"")
C12: =IF($B12="","",IFERROR(VLOOKUP($B12,SPEC,2,0),"NOT FOUND")) | E12: =IF($B12="","",IF(NOT(ISNUMBER($C12)),"CHECK",IF(VLOOKUP($B12,SPEC,3,0)="per m",IF(N($D12)=0,"LEN?",$C12*$D12),$C12))) | G12: =IF($B12="","",IF(ISNUMBER($E12),$E12*N($F12),"CHECK")) | H12: =IF($B12="","",IF(N(IFERROR(VLOOKUP($B12,SPEC,4,0),0))>0,VLOOKUP($B12,SPEC,4,0),"–")) | I12: =IF(ISNUMBER($H12),0+$G$13+$G$22+$G$27+$G$34,"") | J12: =IF(ISNUMBER($I12),$I12*(1+N($F$46)),"") | K12: =IF(ISNUMBER($J12),$J12/$H12,"")
A13: HOIST – body, chain, bag and hoist cables | F13: Subtotal | G13: =SUM(G14:G21) -> 85.334
A14: Hoist | B14: Lodestar D8 LL 1000 Kg 1 Fall 7.92 x 21.80 | C14: =IF($B14="","",IFERROR(VLOOKUP($B14,SPEC,2,0),"NOT FOUND")) -> 54 | E14: =IF($B14="","",IF(NOT(ISNUMBER($C14)),"CHECK",IF(VLOOKUP($B14,SPEC,3,0)="per m",IF(N($D14)=0,"LEN?",$C14*$D14),$C14))) -> 54 | F14: 1 | G14: =IF($B14="","",IF(ISNUMBER($E14),$E14*N($F14),"CHECK")) -> 54 | H14: =IF($B14="","",IF(N(IFERROR(VLOOKUP($B14,SPEC,4,0),0))>0,VLOOKUP($B14,SPEC,4,0),"–")) -> 1000 | I14: =IF(ISNUMBER($H14),IF($E$5="Body up",0,$G$13)+$G$22+$G$27+$G$34,"") -> 444.662 | J14: =IF(ISNUMBER($I14),$I14*(1+N($F$46)),"") -> 466.8951 | K14: =IF(ISNUMBER($J14),$J14/$H14,"") -> 0.4668951
A15: Hoist Chain | B15: CM 7.92 x 21.80 1 Fall | C15: =IF($B15="","",IFERROR(VLOOKUP($B15,SPEC,2,0),"NOT FOUND")) -> 1.4 | D15: 20 | E15: =IF($B15="","",IF(NOT(ISNUMBER($C15)),"CHECK",IF(VLOOKUP($B15,SPEC,3,0)="per m",IF(N($D15)=0,"LEN?",$C15*$D15),$C15))) -> 28 | F15: 1 | G15: =IF($B15="","",IF(ISNUMBER($E15),$E15*N($F15),"CHECK")) -> 28 | H15: =IF($B15="","",IF(N(IFERROR(VLOOKUP($B15,SPEC,4,0),0))>0,VLOOKUP($B15,SPEC,4,0),"–")) -> – | I15: =IF(ISNUMBER($H15),IF($E$5="Body up",0,$G$13)+$G$22+$G$27+$G$34,"") | J15: =IF(ISNUMBER($I15),$I15*(1+N($F$46)),"") | K15: =IF(ISNUMBER($J15),$J15/$H15,"")
A16: Hoist Chain Bag | C16: =IF($B16="","",IFERROR(VLOOKUP($B16,SPEC,2,0),"NOT FOUND")) | E16: =IF($B16="","",IF(NOT(ISNUMBER($C16)),"CHECK",IF(VLOOKUP($B16,SPEC,3,0)="per m",IF(N($D16)=0,"LEN?",$C16*$D16),$C16))) | F16: 1 | G16: =IF($B16="","",IF(ISNUMBER($E16),$E16*N($F16),"CHECK")) | H16: =IF($B16="","",IF(N(IFERROR(VLOOKUP($B16,SPEC,4,0),0))>0,VLOOKUP($B16,SPEC,4,0),"–")) | I16: =IF(ISNUMBER($H16),IF($E$5="Body up",0,$G$13)+$G$22+$G$27+$G$34,"") | J16: =IF(ISNUMBER($I16),$I16*(1+N($F$46)),"") | K16: =IF(ISNUMBER($J16),$J16/$H16,"")
A17: Hoist Power | B17: H07RN-F 4x 2.5mm² | C17: =IF($B17="","",IFERROR(VLOOKUP($B17,SPEC,2,0),"NOT FOUND")) -> 0.26 | D17: 8 | E17: =IF($B17="","",IF(NOT(ISNUMBER($C17)),"CHECK",IF(VLOOKUP($B17,SPEC,3,0)="per m",IF(N($D17)=0,"LEN?",$C17*$D17),$C17))) -> 2.08 | F17: 1 | G17: =IF($B17="","",IF(ISNUMBER($E17),$E17*N($F17),"CHECK")) -> 2.08 | H17: =IF($B17="","",IF(N(IFERROR(VLOOKUP($B17,SPEC,4,0),0))>0,VLOOKUP($B17,SPEC,4,0),"–")) -> – | I17: =IF(ISNUMBER($H17),IF($E$5="Body up",0,$G$13)+$G$22+$G$27+$G$34,"") | J17: =IF(ISNUMBER($I17),$I17*(1+N($F$46)),"") | K17: =IF(ISNUMBER($J17),$J17/$H17,"")
A18: Hoist Control | B18: H07RN-F 3x 2.5mm² | C18: =IF($B18="","",IFERROR(VLOOKUP($B18,SPEC,2,0),"NOT FOUND")) -> 0.123 | D18: 8 | E18: =IF($B18="","",IF(NOT(ISNUMBER($C18)),"CHECK",IF(VLOOKUP($B18,SPEC,3,0)="per m",IF(N($D18)=0,"LEN?",$C18*$D18),$C18))) -> 0.984 | F18: 1 | G18: =IF($B18="","",IF(ISNUMBER($E18),$E18*N($F18),"CHECK")) -> 0.984 | H18: =IF($B18="","",IF(N(IFERROR(VLOOKUP($B18,SPEC,4,0),0))>0,VLOOKUP($B18,SPEC,4,0),"–")) -> – | I18: =IF(ISNUMBER($H18),IF($E$5="Body up",0,$G$13)+$G$22+$G$27+$G$34,"") | J18: =IF(ISNUMBER($I18),$I18*(1+N($F$46)),"") | K18: =IF(ISNUMBER($J18),$J18/$H18,"")
A19: Hoist Control Connector | B19: PCE Midnight IP44 Shark 16A Plug 3 Pole | C19: =IF($B19="","",IFERROR(VLOOKUP($B19,SPEC,2,0),"NOT FOUND")) -> 0.109 | E19: =IF($B19="","",IF(NOT(ISNUMBER($C19)),"CHECK",IF(VLOOKUP($B19,SPEC,3,0)="per m",IF(N($D19)=0,"LEN?",$C19*$D19),$C19))) -> 0.109 | F19: 1 | G19: =IF($B19="","",IF(ISNUMBER($E19),$E19*N($F19),"CHECK")) -> 0.109 | H19: =IF($B19="","",IF(N(IFERROR(VLOOKUP($B19,SPEC,4,0),0))>0,VLOOKUP($B19,SPEC,4,0),"–")) -> – | I19: =IF(ISNUMBER($H19),IF($E$5="Body up",0,$G$13)+$G$22+$G$27+$G$34,"") | J19: =IF(ISNUMBER($I19),$I19*(1+N($F$46)),"") | K19: =IF(ISNUMBER($J19),$J19/$H19,"")
A20: Hoist Power Connector | B20: PCE Midnight IP44 Shark 16A Socket 4 Pole | C20: =IF($B20="","",IFERROR(VLOOKUP($B20,SPEC,2,0),"NOT FOUND")) -> 0.161 | E20: =IF($B20="","",IF(NOT(ISNUMBER($C20)),"CHECK",IF(VLOOKUP($B20,SPEC,3,0)="per m",IF(N($D20)=0,"LEN?",$C20*$D20),$C20))) -> 0.161 | F20: 1 | G20: =IF($B20="","",IF(ISNUMBER($E20),$E20*N($F20),"CHECK")) -> 0.161 | H20: =IF($B20="","",IF(N(IFERROR(VLOOKUP($B20,SPEC,4,0),0))>0,VLOOKUP($B20,SPEC,4,0),"–")) -> – | I20: =IF(ISNUMBER($H20),IF($E$5="Body up",0,$G$13)+$G$22+$G$27+$G$34,"") | J20: =IF(ISNUMBER($I20),$I20*(1+N($F$46)),"") | K20: =IF(ISNUMBER($J20),$J20/$H20,"")
C21: =IF($B21="","",IFERROR(VLOOKUP($B21,SPEC,2,0),"NOT FOUND")) | E21: =IF($B21="","",IF(NOT(ISNUMBER($C21)),"CHECK",IF(VLOOKUP($B21,SPEC,3,0)="per m",IF(N($D21)=0,"LEN?",$C21*$D21),$C21))) | G21: =IF($B21="","",IF(ISNUMBER($E21),$E21*N($F21),"CHECK")) | H21: =IF($B21="","",IF(N(IFERROR(VLOOKUP($B21,SPEC,4,0),0))>0,VLOOKUP($B21,SPEC,4,0),"–")) | I21: =IF(ISNUMBER($H21),IF($E$5="Body up",0,$G$13)+$G$22+$G$27+$G$34,"") | J21: =IF(ISNUMBER($I21),$I21*(1+N($F$46)),"") | K21: =IF(ISNUMBER($J21),$J21/$H21,"")
A22: HOOK / JUNCTION – below the hoist, feeds both paths | F22: Subtotal | G22: =SUM(G23:G26) -> 2.36
A23: Shackles | B23: Crosby S-209T Theatrical Shackle 3¼t | C23: =IF($B23="","",IFERROR(VLOOKUP($B23,SPEC,2,0),"NOT FOUND")) -> 0.62 | E23: =IF($B23="","",IF(NOT(ISNUMBER($C23)),"CHECK",IF(VLOOKUP($B23,SPEC,3,0)="per m",IF(N($D23)=0,"LEN?",$C23*$D23),$C23))) -> 0.62 | F23: 3 | G23: =IF($B23="","",IF(ISNUMBER($E23),$E23*N($F23),"CHECK")) -> 1.86 | H23: =IF($B23="","",IF(N(IFERROR(VLOOKUP($B23,SPEC,4,0),0))>0,VLOOKUP($B23,SPEC,4,0),"–")) -> 3250 | I23: =IF(ISNUMBER($H23),SUM($G$24:$G$26)+$G$27+$G$34,"") -> 357.468 | J23: =IF(ISNUMBER($I23),$I23*(1+N($F$46)),"") -> 375.3414 | K23: =IF(ISNUMBER($J23),$J23/$H23,"") -> 0.11548966
A24: Master Link | B24: Grade 80 Masterlink ML/A16 2.5t WLL | C24: =IF($B24="","",IFERROR(VLOOKUP($B24,SPEC,2,0),"NOT FOUND")) -> 0.5 | E24: =IF($B24="","",IF(NOT(ISNUMBER($C24)),"CHECK",IF(VLOOKUP($B24,SPEC,3,0)="per m",IF(N($D24)=0,"LEN?",$C24*$D24),$C24))) -> 0.5 | F24: 1 | G24: =IF($B24="","",IF(ISNUMBER($E24),$E24*N($F24),"CHECK")) -> 0.5 | H24: =IF($B24="","",IF(N(IFERROR(VLOOKUP($B24,SPEC,4,0),0))>0,VLOOKUP($B24,SPEC,4,0),"–")) -> 2500 | I24: =IF(ISNUMBER($H24),SUM($G$25:$G$26)+$G$27+$G$34,"") -> 356.968 | J24: =IF(ISNUMBER($I24),$I24*(1+N($F$46)),"") -> 374.8164 | K24: =IF(ISNUMBER($J24),$J24/$H24,"") -> 0.14992656
C25: =IF($B25="","",IFERROR(VLOOKUP($B25,SPEC,2,0),"NOT FOUND")) | E25: =IF($B25="","",IF(NOT(ISNUMBER($C25)),"CHECK",IF(VLOOKUP($B25,SPEC,3,0)="per m",IF(N($D25)=0,"LEN?",$C25*$D25),$C25))) | G25: =IF($B25="","",IF(ISNUMBER($E25),$E25*N($F25),"CHECK")) | H25: =IF($B25="","",IF(N(IFERROR(VLOOKUP($B25,SPEC,4,0),0))>0,VLOOKUP($B25,SPEC,4,0),"–")) | I25: =IF(ISNUMBER($H25),SUM($G$26:$G$26)+$G$27+$G$34,"") | J25: =IF(ISNUMBER($I25),$I25*(1+N($F$46)),"") | K25: =IF(ISNUMBER($J25),$J25/$H25,"")
C26: =IF($B26="","",IFERROR(VLOOKUP($B26,SPEC,2,0),"NOT FOUND")) | E26: =IF($B26="","",IF(NOT(ISNUMBER($C26)),"CHECK",IF(VLOOKUP($B26,SPEC,3,0)="per m",IF(N($D26)=0,"LEN?",$C26*$D26),$C26))) | G26: =IF($B26="","",IF(ISNUMBER($E26),$E26*N($F26),"CHECK")) | H26: =IF($B26="","",IF(N(IFERROR(VLOOKUP($B26,SPEC,4,0),0))>0,VLOOKUP($B26,SPEC,4,0),"–")) | I26: =IF(ISNUMBER($H26),0+$G$27+$G$34,"") | J26: =IF(ISNUMBER($I26),$I26*(1+N($F$46)),"") | K26: =IF(ISNUMBER($J26),$J26/$H26,"")
A27: LOAD PATH 1 – ARRAY (list top-down) | F27: Subtotal | G27: =SUM(G28:G33) -> 342
A28: Rigging Frame | B28: L-Acoustics M-BAR | C28: =IF($B28="","",IFERROR(VLOOKUP($B28,SPEC,2,0),"NOT FOUND")) -> 5 | E28: =IF($B28="","",IF(NOT(ISNUMBER($C28)),"CHECK",IF(VLOOKUP($B28,SPEC,3,0)="per m",IF(N($D28)=0,"LEN?",$C28*$D28),$C28))) -> 5 | F28: 1 | G28: =IF($B28="","",IF(ISNUMBER($E28),$E28*N($F28),"CHECK")) -> 5 | H28: =IF($B28="","",IF(N(IFERROR(VLOOKUP($B28,SPEC,4,0),0))>0,VLOOKUP($B28,SPEC,4,0),"–")) -> 860 | I28: =IF(ISNUMBER($H28),SUM($G$29:$G$33),"") -> 337 | J28: =IF(ISNUMBER($I28),$I28*(1+N($F$46)),"") -> 353.85 | K28: =IF(ISNUMBER($J28),$J28/$H28,"") -> 0.41145349
A29: Rigging Frame | B29: L-Acoustics M-BUMP | C29: =IF($B29="","",IFERROR(VLOOKUP($B29,SPEC,2,0),"NOT FOUND")) -> 25 | E29: =IF($B29="","",IF(NOT(ISNUMBER($C29)),"CHECK",IF(VLOOKUP($B29,SPEC,3,0)="per m",IF(N($D29)=0,"LEN?",$C29*$D29),$C29))) -> 25 | F29: 1 | G29: =IF($B29="","",IF(ISNUMBER($E29),$E29*N($F29),"CHECK")) -> 25 | H29: =IF($B29="","",IF(N(IFERROR(VLOOKUP($B29,SPEC,4,0),0))>0,VLOOKUP($B29,SPEC,4,0),"–")) -> 832 | I29: =IF(ISNUMBER($H29),SUM($G$30:$G$33),"") -> 312 | J29: =IF(ISNUMBER($I29),$I29*(1+N($F$46)),"") -> 327.6 | K29: =IF(ISNUMBER($J29),$J29/$H29,"") -> 0.39375
A30: Mid Hi Box | B30: L-Acoustics KARA II | C30: =IF($B30="","",IFERROR(VLOOKUP($B30,SPEC,2,0),"NOT FOUND")) -> 26 | E30: =IF($B30="","",IF(NOT(ISNUMBER($C30)),"CHECK",IF(VLOOKUP($B30,SPEC,3,0)="per m",IF(N($D30)=0,"LEN?",$C30*$D30),$C30))) -> 26 | F30: 12 | G30: =IF($B30="","",IF(ISNUMBER($E30),$E30*N($F30),"CHECK")) -> 312 | H30: =IF($B30="","",IF(N(IFERROR(VLOOKUP($B30,SPEC,4,0),0))>0,VLOOKUP($B30,SPEC,4,0),"–")) -> – | I30: =IF(ISNUMBER($H30),SUM($G$31:$G$33),"") | J30: =IF(ISNUMBER($I30),$I30*(1+N($F$46)),"") | K30: =IF(ISNUMBER($J30),$J30/$H30,"")
C31: =IF($B31="","",IFERROR(VLOOKUP($B31,SPEC,2,0),"NOT FOUND")) | E31: =IF($B31="","",IF(NOT(ISNUMBER($C31)),"CHECK",IF(VLOOKUP($B31,SPEC,3,0)="per m",IF(N($D31)=0,"LEN?",$C31*$D31),$C31))) | G31: =IF($B31="","",IF(ISNUMBER($E31),$E31*N($F31),"CHECK")) | H31: =IF($B31="","",IF(N(IFERROR(VLOOKUP($B31,SPEC,4,0),0))>0,VLOOKUP($B31,SPEC,4,0),"–")) | I31: =IF(ISNUMBER($H31),SUM($G$32:$G$33),"") | J31: =IF(ISNUMBER($I31),$I31*(1+N($F$46)),"") | K31: =IF(ISNUMBER($J31),$J31/$H31,"")
C32: =IF($B32="","",IFERROR(VLOOKUP($B32,SPEC,2,0),"NOT FOUND")) | E32: =IF($B32="","",IF(NOT(ISNUMBER($C32)),"CHECK",IF(VLOOKUP($B32,SPEC,3,0)="per m",IF(N($D32)=0,"LEN?",$C32*$D32),$C32))) | G32: =IF($B32="","",IF(ISNUMBER($E32),$E32*N($F32),"CHECK")) | H32: =IF($B32="","",IF(N(IFERROR(VLOOKUP($B32,SPEC,4,0),0))>0,VLOOKUP($B32,SPEC,4,0),"–")) | I32: =IF(ISNUMBER($H32),SUM($G$33:$G$33),"") | J32: =IF(ISNUMBER($I32),$I32*(1+N($F$46)),"") | K32: =IF(ISNUMBER($J32),$J32/$H32,"")
C33: =IF($B33="","",IFERROR(VLOOKUP($B33,SPEC,2,0),"NOT FOUND")) | E33: =IF($B33="","",IF(NOT(ISNUMBER($C33)),"CHECK",IF(VLOOKUP($B33,SPEC,3,0)="per m",IF(N($D33)=0,"LEN?",$C33*$D33),$C33))) | G33: =IF($B33="","",IF(ISNUMBER($E33),$E33*N($F33),"CHECK")) | H33: =IF($B33="","",IF(N(IFERROR(VLOOKUP($B33,SPEC,4,0),0))>0,VLOOKUP($B33,SPEC,4,0),"–")) | I33: =IF(ISNUMBER($H33),0,"") | J33: =IF(ISNUMBER($I33),$I33*(1+N($F$46)),"") | K33: =IF(ISNUMBER($J33),$J33/$H33,"")
A34: LOAD PATH 2 – CABLES & CABLE PICK (list top-down) | F34: Subtotal | G34: =SUM(G35:G40) -> 14.968
A35: Cable Pick | B35: Roundsling 2t EN1492-2:2000 1.0mtr Circ 0.5mtr EWL | C35: =IF($B35="","",IFERROR(VLOOKUP($B35,SPEC,2,0),"NOT FOUND")) -> 0.04 | E35: =IF($B35="","",IF(NOT(ISNUMBER($C35)),"CHECK",IF(VLOOKUP($B35,SPEC,3,0)="per m",IF(N($D35)=0,"LEN?",$C35*$D35),$C35))) -> 0.04 | F35: 1 | G35: =IF($B35="","",IF(ISNUMBER($E35),$E35*N($F35),"CHECK")) -> 0.04 | H35: =IF($B35="","",IF(N(IFERROR(VLOOKUP($B35,SPEC,4,0),0))>0,VLOOKUP($B35,SPEC,4,0),"–")) -> 2000 | I35: =IF(ISNUMBER($H35),SUM($G$36:$G$40),"") -> 14.928 | J35: =IF(ISNUMBER($I35),$I35*(1+N($F$46)),"") -> 15.6744 | K35: =IF(ISNUMBER($J35),$J35/$H35,"") -> 0.0078372
A36: Array Signal | B36: Klotz eXtreme, 8 x 4,0 mm² with PA-COM 8p | C36: =IF($B36="","",IFERROR(VLOOKUP($B36,SPEC,2,0),"NOT FOUND")) -> 0.6955 | D36: 8 | E36: =IF($B36="","",IF(NOT(ISNUMBER($C36)),"CHECK",IF(VLOOKUP($B36,SPEC,3,0)="per m",IF(N($D36)=0,"LEN?",$C36*$D36),$C36))) -> 5.564 | F36: 2 | G36: =IF($B36="","",IF(ISNUMBER($E36),$E36*N($F36),"CHECK")) -> 11.128 | H36: =IF($B36="","",IF(N(IFERROR(VLOOKUP($B36,SPEC,4,0),0))>0,VLOOKUP($B36,SPEC,4,0),"–")) -> – | I36: =IF(ISNUMBER($H36),SUM($G$37:$G$40),"") | J36: =IF(ISNUMBER($I36),$I36*(1+N($F$46)),"") | K36: =IF(ISNUMBER($J36),$J36/$H36,"")
A37: Cable Split | B37: Klotz L-ACOUSTICS DOFILL | C37: =IF($B37="","",IFERROR(VLOOKUP($B37,SPEC,2,0),"NOT FOUND")) -> 1.9 | E37: =IF($B37="","",IF(NOT(ISNUMBER($C37)),"CHECK",IF(VLOOKUP($B37,SPEC,3,0)="per m",IF(N($D37)=0,"LEN?",$C37*$D37),$C37))) -> 1.9 | F37: 2 | G37: =IF($B37="","",IF(ISNUMBER($E37),$E37*N($F37),"CHECK")) -> 3.8 | H37: =IF($B37="","",IF(N(IFERROR(VLOOKUP($B37,SPEC,4,0),0))>0,VLOOKUP($B37,SPEC,4,0),"–")) -> – | I37: =IF(ISNUMBER($H37),SUM($G$38:$G$40),"") | J37: =IF(ISNUMBER($I37),$I37*(1+N($F$46)),"") | K37: =IF(ISNUMBER($J37),$J37/$H37,"")
C38: =IF($B38="","",IFERROR(VLOOKUP($B38,SPEC,2,0),"NOT FOUND")) | E38: =IF($B38="","",IF(NOT(ISNUMBER($C38)),"CHECK",IF(VLOOKUP($B38,SPEC,3,0)="per m",IF(N($D38)=0,"LEN?",$C38*$D38),$C38))) | G38: =IF($B38="","",IF(ISNUMBER($E38),$E38*N($F38),"CHECK")) | H38: =IF($B38="","",IF(N(IFERROR(VLOOKUP($B38,SPEC,4,0),0))>0,VLOOKUP($B38,SPEC,4,0),"–")) | I38: =IF(ISNUMBER($H38),SUM($G$39:$G$40),"") | J38: =IF(ISNUMBER($I38),$I38*(1+N($F$46)),"") | K38: =IF(ISNUMBER($J38),$J38/$H38,"")
C39: =IF($B39="","",IFERROR(VLOOKUP($B39,SPEC,2,0),"NOT FOUND")) | E39: =IF($B39="","",IF(NOT(ISNUMBER($C39)),"CHECK",IF(VLOOKUP($B39,SPEC,3,0)="per m",IF(N($D39)=0,"LEN?",$C39*$D39),$C39))) | G39: =IF($B39="","",IF(ISNUMBER($E39),$E39*N($F39),"CHECK")) | H39: =IF($B39="","",IF(N(IFERROR(VLOOKUP($B39,SPEC,4,0),0))>0,VLOOKUP($B39,SPEC,4,0),"–")) | I39: =IF(ISNUMBER($H39),SUM($G$40:$G$40),"") | J39: =IF(ISNUMBER($I39),$I39*(1+N($F$46)),"") | K39: =IF(ISNUMBER($J39),$J39/$H39,"")
C40: =IF($B40="","",IFERROR(VLOOKUP($B40,SPEC,2,0),"NOT FOUND")) | E40: =IF($B40="","",IF(NOT(ISNUMBER($C40)),"CHECK",IF(VLOOKUP($B40,SPEC,3,0)="per m",IF(N($D40)=0,"LEN?",$C40*$D40),$C40))) | G40: =IF($B40="","",IF(ISNUMBER($E40),$E40*N($F40),"CHECK")) | H40: =IF($B40="","",IF(N(IFERROR(VLOOKUP($B40,SPEC,4,0),0))>0,VLOOKUP($B40,SPEC,4,0),"–")) | I40: =IF(ISNUMBER($H40),0,"") | J40: =IF(ISNUMBER($I40),$I40*(1+N($F$46)),"") | K40: =IF(ISNUMBER($J40),$J40/$H40,"")
A41: TOTAL STATIC WEIGHT | G41: =G9+G13+G22+G27+G34 -> 444.662
...

Sheet Spec
A1: Item | B1: Kg | C1: Per | D1: SWL (kg)
A2: VAN DAMME TOUR GRADE CLASSIC XKE STARQUAD MICROPHONE CABLE | B2: TBC | C2: per m
A3: Van Damme Black Series Tour Grade 4 x 2.5mm² | B3: TBC | C3: per m
A4: Van Damme Black Series Tour Grade 6 x 2.5mm² | B4: TBC | C4: per m
A5: Van Damme Black Series Tour Grade 8 x 2.5mm² | B5: TBC | C5: per m
A6: Van Damme Black Series Tour Grade 4 x 4.0mm² | B6: TBC | C6: per m
A7: Van Damme Black Series Tour Grade 8 x 4.0mm² | B7: TBC | C7: per m
A8: Van Damme Black Series Tour Grade 18 x 1.5mm² | B8: TBC | C8: per m
A9: Van Damme Black Series Tour Grade 18 x 2.5mm² | B9: TBC | C9: per m
A10: Van Damme Black Series Tour Grade 16 x 4.0mm² | B10: TBC | C10: per m
A11: Van Damme Black Series Tour Grade 24 x 4.0mm² | B11: TBC | C11: per m
A12: Klotz eXtreme, 24x 4,0 mm² with PA-COM 25p | B12: =83.78/50 -> 1.6756 | C12: per m
A13: Klotz eXtreme, 8 x 4,0 mm² with PA-COM 8p | B13: =27.82/40 -> 0.6955 | C13: per m
A14: Klotz eXtreme, 8 x 4.0 mm² with metal speakON | B14: =14.93/30 -> 0.49766667 | C14: per m
A15: Klotz eXtreme, 4 x 4,0 mm² with metal speakON | B15: =8.27/30 -> 0.27566667 | C15: per m
A16: H07RN-F 2x 1.0mm² | B16: =94/1000 -> 0.094 | C16: per m
A17: H07RN-F 2x 1.5mm² | B17: =120/1000 -> 0.12 | C17: per m
A18: H07RN-F 2x 2.5mm² | B18: =173/1000 -> 0.173 | C18: per m
A19: H07RN-F 2x 4.0mm² | B19: =239/1000 -> 0.239 | C19: per m
A20: H07RN-F 2x 6.0mm² | B20: =313/1000 -> 0.313 | C20: per m
A21: H07RN-F 2x 10mm² | B21: =563/1000 -> 0.563 | C21: per m
A22: H07RN-F 2x 16mm² | B22: =830/1000 -> 0.83 | C22: per m
A23: H07RN-F 3x 1.0mm² | B23: =117/1000 -> 0.117 | C23: per m
A24: H07RN-F 3x 1.5mm² | B24: =147/1000 -> 0.147 | C24: per m
A25: H07RN-F 3x 2.5mm² | B25: =123/1000 -> 0.123 | C25: per m
A26: H07RN-F 3x 4.0mm² | B26: =297/1000 -> 0.297 | C26: per m
A27: H07RN-F 3x 6.0mm² | B27: =390/1000 -> 0.39 | C27: per m
A28: H07RN-F 3x 10mm² | B28: =705/1000 -> 0.705 | C28: per m
A29: H07RN-F 3x 16mm² | B29: =1031/1000 -> 1.031 | C29: per m
A30: H07RN-F 4x 1.0mm² | B30: =142/1000 -> 0.142 | C30: per m
A31: H07RN-F 4x 1.5mm² | B31: =180/1000 -> 0.18 | C31: per m
A32: H07RN-F 4x 2.5mm² | B32: =260/1000 -> 0.26 | C32: per m
A33: H07RN-F 4x 4.0mm² | B33: =336/1000 -> 0.336 | C33: per m
A34: H07RN-F 4x 6.0mm² | B34: =449/1000 -> 0.449 | C34: per m
A35: H07RN-F 4x 10mm² | B35: =833/1000 -> 0.833 | C35: per m
A36: H07RN-F 4x 16mm² | B36: =1138/1000 -> 1.138 | C36: per m
A37: H07RN-F 5x 1.5mm² | B37: =206/1000 -> 0.206 | C37: per m
A38: H07RN-F 5x 2.5mm² | B38: =297/1000 -> 0.297 | C38: per m
A39: H07RN-F 5x 4.0mm² | B39: =422/1000 -> 0.422 | C39: per m
A40: H07RN-F 5x 6.0mm² | B40: =567/1000 -> 0.567 | C40: per m
...

Sheet Load Sheet
A1: FLOWN ARRAY LOAD SHEET
A2: Static load-path analysis – single hang
A4: Job: | B4: =IF(Calc!B1="","",Calc!B1) -> The Ballroom | D4: Status: | G4: =IF(Calc!E1="","",Calc!E1) -> Draft
A5: Venue: | B5: =IF(Calc!B4="","",Calc!B4) | D5: Revision: | G5: =IF(Calc!E2="","",Calc!E2)
A6: Sub System: | B6: =IF(Calc!B5="","",Calc!B5) -> Main Hang Left | D6: Job Date: | G6: =IF(Calc!B2="","",Calc!B2)
A7: Point ID / Location: | B7: =IF(Calc!B6="","",Calc!B6) | D7: Designer: | G7: =IF(Calc!B3="","",Calc!B3) -> Mark Hughes
A8: Load over people? | B8: =IF(Calc!E3="","– not stated –",Calc!E3) -> – not stated – | D8: Hoist orientation: | G8: =IF(Calc!E5="","",Calc!E5) -> Body down
A9: Top rigging included? | B9: =IF(Calc!E4="","– not stated –",Calc!E4) -> Yes | D9: Sheet Date:
A11: NOTES | B11: ITEM | C11: Qty | D11: Length (m) | E11: Weight | F11: SWL / WLL | G11: ="Carried load (+"&TEXT(Calc!F46,"0%")&")" -> Carried load (+5%) | H11: Used
A12: =Calc!A9 -> TOP RIGGING – above the hoist (list top-down) | E12: =Calc!G9 -> 0
A13: =IF(Calc!A10="","",Calc!A10) -> Steel | B13: =IF(Calc!B10="","",Calc!B10) -> Wire rope sling 10mm 1,280 Kg SWL EN13414-1:2003 | C13: =IF(Calc!F10="","",Calc!F10) -> 1 | D13: =IF(Calc!D10="","",Calc!D10) -> 1 | E13: =IF(Calc!G10="","",Calc!G10) -> CHECK | F13: =IF(Calc!H10="","",Calc!H10) -> 1280 | G13: =IF(Calc!J10="","",Calc!J10) -> 466.8951 | H13: =IF(Calc!K10="","",Calc!K10) -> 0.3647618
A14: =IF(Calc!A11="","",Calc!A11) | B14: =IF(Calc!B11="","",Calc!B11) | C14: =IF(Calc!F11="","",Calc!F11) | D14: =IF(Calc!D11="","",Calc!D11) | E14: =IF(Calc!G11="","",Calc!G11) | F14: =IF(Calc!H11="","",Calc!H11) | G14: =IF(Calc!J11="","",Calc!J11) | H14: =IF(Calc!K11="","",Calc!K11)
A15: =IF(Calc!A12="","",Calc!A12) | B15: =IF(Calc!B12="","",Calc!B12) | C15: =IF(Calc!F12="","",Calc!F12) | D15: =IF(Calc!D12="","",Calc!D12) | E15: =IF(Calc!G12="","",Calc!G12) | F15: =IF(Calc!H12="","",Calc!H12) | G15: =IF(Calc!J12="","",Calc!J12) | H15: =IF(Calc!K12="","",Calc!K12)
A16: =Calc!A13 -> HOIST – body, chain, bag and hoist cables | E16: =Calc!G13 -> 85.334
A17: =IF(Calc!A14="","",Calc!A14) -> Hoist | B17: =IF(Calc!B14="","",Calc!B14) -> Lodestar D8 LL 1000 Kg 1 Fall 7.92 x 21.80 | C17: =IF(Calc!F14="","",Calc!F14) -> 1 | D17: =IF(Calc!D14="","",Calc!D14) | E17: =IF(Calc!G14="","",Calc!G14) -> 54 | F17: =IF(Calc!H14="","",Calc!H14) -> 1000 | G17: =IF(Calc!J14="","",Calc!J14) -> 466.8951 | H17: =IF(Calc!K14="","",Calc!K14) -> 0.4668951
A18: =IF(Calc!A15="","",Calc!A15) -> Hoist Chain | B18: =IF(Calc!B15="","",Calc!B15) -> CM 7.92 x 21.80 1 Fall | C18: =IF(Calc!F15="","",Calc!F15) -> 1 | D18: =IF(Calc!D15="","",Calc!D15) -> 20 | E18: =IF(Calc!G15="","",Calc!G15) -> 28 | F18: =IF(Calc!H15="","",Calc!H15) -> – | G18: =IF(Calc!J15="","",Calc!J15) | H18: =IF(Calc!K15="","",Calc!K15)
A19: =IF(Calc!A16="","",Calc!A16) -> Hoist Chain Bag | B19: =IF(Calc!B16="","",Calc!B16) | C19: =IF(Calc!F16="","",Calc!F16) -> 1 | D19: =IF(Calc!D16="","",Calc!D16) | E19: =IF(Calc!G16="","",Calc!G16) | F19: =IF(Calc!H16="","",Calc!H16) | G19: =IF(Calc!J16="","",Calc!J16) | H19: =IF(Calc!K16="","",Calc!K16)
A20: =IF(Calc!A17="","",Calc!A17) -> Hoist Power | B20: =IF(Calc!B17="","",Calc!B17) -> H07RN-F 4x 2.5mm² | C20: =IF(Calc!F17="","",Calc!F17) -> 1 | D20: =IF(Calc!D17="","",Calc!D17) -> 8 | E20: =IF(Calc!G17="","",Calc!G17) -> 2.08 | F20: =IF(Calc!H17="","",Calc!H17) -> – | G20: =IF(Calc!J17="","",Calc!J17) | H20: =IF(Calc!K17="","",Calc!K17)
A21: =IF(Calc!A18="","",Calc!A18) -> Hoist Control | B21: =IF(Calc!B18="","",Calc!B18) -> H07RN-F 3x 2.5mm² | C21: =IF(Calc!F18="","",Calc!F18) -> 1 | D21: =IF(Calc!D18="","",Calc!D18) -> 8 | E21: =IF(Calc!G18="","",Calc!G18) -> 0.984 | F21: =IF(Calc!H18="","",Calc!H18) -> – | G21: =IF(Calc!J18="","",Calc!J18) | H21: =IF(Calc!K18="","",Calc!K18)
A22: =IF(Calc!A19="","",Calc!A19) -> Hoist Control Connector | B22: =IF(Calc!B19="","",Calc!B19) -> PCE Midnight IP44 Shark 16A Plug 3 Pole | C22: =IF(Calc!F19="","",Calc!F19) -> 1 | D22: =IF(Calc!D19="","",Calc!D19) | E22: =IF(Calc!G19="","",Calc!G19) -> 0.109 | F22: =IF(Calc!H19="","",Calc!H19) -> – | G22: =IF(Calc!J19="","",Calc!J19) | H22: =IF(Calc!K19="","",Calc!K19)
A23: =IF(Calc!A20="","",Calc!A20) -> Hoist Power Connector | B23: =IF(Calc!B20="","",Calc!B20) -> PCE Midnight IP44 Shark 16A Socket 4 Pole | C23: =IF(Calc!F20="","",Calc!F20) -> 1 | D23: =IF(Calc!D20="","",Calc!D20) | E23: =IF(Calc!G20="","",Calc!G20) -> 0.161 | F23: =IF(Calc!H20="","",Calc!H20) -> – | G23: =IF(Calc!J20="","",Calc!J20) | H23: =IF(Calc!K20="","",Calc!K20)
A24: =IF(Calc!A21="","",Calc!A21) | B24: =IF(Calc!B21="","",Calc!B21) | C24: =IF(Calc!F21="","",Calc!F21) | D24: =IF(Calc!D21="","",Calc!D21) | E24: =IF(Calc!G21="","",Calc!G21) | F24: =IF(Calc!H21="","",Calc!H21) | G24: =IF(Calc!J21="","",Calc!J21) | H24: =IF(Calc!K21="","",Calc!K21)
A25: =Calc!A22 -> HOOK / JUNCTION – below the hoist, feeds both paths | E25: =Calc!G22 -> 2.36
A26: =IF(Calc!A23="","",Calc!A23) -> Shackles | B26: =IF(Calc!B23="","",Calc!B23) -> Crosby S-209T Theatrical Shackle 3¼t | C26: =IF(Calc!F23="","",Calc!F23) -> 3 | D26: =IF(Calc!D23="","",Calc!D23) | E26: =IF(Calc!G23="","",Calc!G23) -> 1.86 | F26: =IF(Calc!H23="","",Calc!H23) -> 3250 | G26: =IF(Calc!J23="","",Calc!J23) -> 375.3414 | H26: =IF(Calc!K23="","",Calc!K23) -> 0.11548966
A27: =IF(Calc!A24="","",Calc!A24) -> Master Link | B27: =IF(Calc!B24="","",Calc!B24) -> Grade 80 Masterlink ML/A16 2.5t WLL | C27: =IF(Calc!F24="","",Calc!F24) -> 1 | D27: =IF(Calc!D24="","",Calc!D24) | E27: =IF(Calc!G24="","",Calc!G24) -> 0.5 | F27: =IF(Calc!H24="","",Calc!H24) -> 2500 | G27: =IF(Calc!J24="","",Calc!J24) -> 374.8164 | H27: =IF(Calc!K24="","",Calc!K24) -> 0.14992656
A28: =IF(Calc!A25="","",Calc!A25) | B28: =IF(Calc!B25="","",Calc!B25) | C28: =IF(Calc!F25="","",Calc!F25) | D28: =IF(Calc!D25="","",Calc!D25) | E28: =IF(Calc!G25="","",Calc!G25) | F28: =IF(Calc!H25="","",Calc!H25) | G28: =IF(Calc!J25="","",Calc!J25) | H28: =IF(Calc!K25="","",Calc!K25)
A29: =IF(Calc!A26="","",Calc!A26) | B29: =IF(Calc!B26="","",Calc!B26) | C29: =IF(Calc!F26="","",Calc!F26) | D29: =IF(Calc!D26="","",Calc!D26) | E29: =IF(Calc!G26="","",Calc!G26) | F29: =IF(Calc!H26="","",Calc!H26) | G29: =IF(Calc!J26="","",Calc!J26) | H29: =IF(Calc!K26="","",Calc!K26)
A30: =Calc!A27 -> LOAD PATH 1 – ARRAY (list top-down) | E30: =Calc!G27 -> 342
A31: =IF(Calc!A28="","",Calc!A28) -> Rigging Frame | B31: =IF(Calc!B28="","",Calc!B28) -> L-Acoustics M-BAR | C31: =IF(Calc!F28="","",Calc!F28) -> 1 | D31: =IF(Calc!D28="","",Calc!D28) | E31: =IF(Calc!G28="","",Calc!G28) -> 5 | F31: =IF(Calc!H28="","",Calc!H28) -> 860 | G31: =IF(Calc!J28="","",Calc!J28) -> 353.85 | H31: =IF(Calc!K28="","",Calc!K28) -> 0.41145349
A32: =IF(Calc!A29="","",Calc!A29) -> Rigging Frame | B32: =IF(Calc!B29="","",Calc!B29) -> L-Acoustics M-BUMP | C32: =IF(Calc!F29="","",Calc!F29) -> 1 | D32: =IF(Calc!D29="","",Calc!D29) | E32: =IF(Calc!G29="","",Calc!G29) -> 25 | F32: =IF(Calc!H29="","",Calc!H29) -> 832 | G32: =IF(Calc!J29="","",Calc!J29) -> 327.6 | H32: =IF(Calc!K29="","",Calc!K29) -> 0.39375
A33: =IF(Calc!A30="","",Calc!A30) -> Mid Hi Box | B33: =IF(Calc!B30="","",Calc!B30) -> L-Acoustics KARA II | C33: =IF(Calc!F30="","",Calc!F30) -> 12 | D33: =IF(Calc!D30="","",Calc!D30) | E33: =IF(Calc!G30="","",Calc!G30) -> 312 | F33: =IF(Calc!H30="","",Calc!H30) -> – | G33: =IF(Calc!J30="","",Calc!J30) | H33: =IF(Calc!K30="","",Calc!K30)
A34: =IF(Calc!A31="","",Calc!A31) | B34: =IF(Calc!B31="","",Calc!B31) | C34: =IF(Calc!F31="","",Calc!F31) | D34: =IF(Calc!D31="","",Calc!D31) | E34: =IF(Calc!G31="","",Calc!G31) | F34: =IF(Calc!H31="","",Calc!H31) | G34: =IF(Calc!J31="","",Calc!J31) | H34: =IF(Calc!K31="","",Calc!K31)
A35: =IF(Calc!A32="","",Calc!A32) | B35: =IF(Calc!B32="","",Calc!B32) | C35: =IF(Calc!F32="","",Calc!F32) | D35: =IF(Calc!D32="","",Calc!D32) | E35: =IF(Calc!G32="","",Calc!G32) | F35: =IF(Calc!H32="","",Calc!H32) | G35: =IF(Calc!J32="","",Calc!J32) | H35: =IF(Calc!K32="","",Calc!K32)
A36: =IF(Calc!A33="","",Calc!A33) | B36: =IF(Calc!B33="","",Calc!B33) | C36: =IF(Calc!F33="","",Calc!F33) | D36: =IF(Calc!D33="","",Calc!D33) | E36: =IF(Calc!G33="","",Calc!G33) | F36: =IF(Calc!H33="","",Calc!H33) | G36: =IF(Calc!J33="","",Calc!J33) | H36: =IF(Calc!K33="","",Calc!K33)
A37: =Calc!A34 -> LOAD PATH 2 – CABLES & CABLE PICK (list top-down) | E37: =Calc!G34 -> 14.968
A38: =IF(Calc!A35="","",Calc!A35) -> Cable Pick | B38: =IF(Calc!B35="","",Calc!B35) -> Roundsling 2t EN1492-2:2000 1.0mtr Circ 0.5mtr EWL | C38: =IF(Calc!F35="","",Calc!F35) -> 1 | D38: =IF(Calc!D35="","",Calc!D35) | E38: =IF(Calc!G35="","",Calc!G35) -> 0.04 | F38: =IF(Calc!H35="","",Calc!H35) -> 2000 | G38: =IF(Calc!J35="","",Calc!J35) -> 15.6744 | H38: =IF(Calc!K35="","",Calc!K35) -> 0.0078372
A39: =IF(Calc!A36="","",Calc!A36) -> Array Signal | B39: =IF(Calc!B36="","",Calc!B36) -> Klotz eXtreme, 8 x 4,0 mm² with PA-COM 8p | C39: =IF(Calc!F36="","",Calc!F36) -> 2 | D39: =IF(Calc!D36="","",Calc!D36) -> 8 | E39: =IF(Calc!G36="","",Calc!G36) -> 11.128 | F39: =IF(Calc!H36="","",Calc!H36) -> – | G39: =IF(Calc!J36="","",Calc!J36) | H39: =IF(Calc!K36="","",Calc!K36)
A40: =IF(Calc!A37="","",Calc!A37) -> Cable Split | B40: =IF(Calc!B37="","",Calc!B37) -> Klotz L-ACOUSTICS DOFILL | C40: =IF(Calc!F37="","",Calc!F37) -> 2 | D40: =IF(Calc!D37="","",Calc!D37) | E40: =IF(Calc!G37="","",Calc!G37) -> 3.8 | F40: =IF(Calc!H37="","",Calc!H37) -> – | G40: =IF(Calc!J37="","",Calc!J37) | H40: =IF(Calc!K37="","",Calc!K37)
A41: =IF(Calc!A38="","",Calc!A38) | B41: =IF(Calc!B38="","",Calc!B38) | C41: =IF(Calc!F38="","",Calc!F38) | D41: =IF(Calc!D38="","",Calc!D38) | E41: =IF(Calc!G38="","",Calc!G38) | F41: =IF(Calc!H38="","",Calc!H38) | G41: =IF(Calc!J38="","",Calc!J38) | H41: =IF(Calc!K38="","",Calc!K38)
A42: =IF(Calc!A39="","",Calc!A39) | B42: =IF(Calc!B39="","",Calc!B39) | C42: =IF(Calc!F39="","",Calc!F39) | D42: =IF(Calc!D39="","",Calc!D39) | E42: =IF(Calc!G39="","",Calc!G39) | F42: =IF(Calc!H39="","",Calc!H39) | G42: =IF(Calc!J39="","",Calc!J39) | H42: =IF(Calc!K39="","",Calc!K39)
...
